{
    "repository": "andreschaffer/microservices-testing-examples",
    "stars": 105,
    "language": "java",
    "size": 497,
    "clone_url": "https://github.com/andreschaffer/microservices-testing-examples.git",
    "timestamp": "2023-06-29T12:39:22.263795Z",
    "clone_success": true,
    "number_of_actions": 1,
    "number_of_test_actions": 1,
    "actions_successful": false,
    "actions_build_tools": [
        "maven"
    ],
    "actions_test_build_tools": [
        "maven"
    ],
    "actions_run": {
        "failed": true,
        "tests": [],
        "stdout": "[2d648874-7e47-496d-8d48-b307b98254c1/build] \ud83d\ude80  Start image=crawlergpt:latest\n[2d648874-7e47-496d-8d48-b307b98254c1/build]   \ud83d\udc33  docker pull image=crawlergpt:latest platform= username= forcePull=false\n[2d648874-7e47-496d-8d48-b307b98254c1/build]   \ud83d\udc33  docker create image=crawlergpt:latest platform= entrypoint=[\"tail\" \"-f\" \"/dev/null\"] cmd=[]\n[2d648874-7e47-496d-8d48-b307b98254c1/build]   \ud83d\udc33  docker run image=crawlergpt:latest platform= entrypoint=[\"tail\" \"-f\" \"/dev/null\"] cmd=[]\n[2d648874-7e47-496d-8d48-b307b98254c1/build]   \ud83d\udc33  docker exec cmd=[chown -R 1012:1013 /tmp/3d783ea4-1661-11ee-8a50-bb14de238602/andreschaffer-microservices-testing-examples] user=0 workdir=\n[2d648874-7e47-496d-8d48-b307b98254c1/build]   \u2601  git clone 'https://github.com/actions/setup-java' # ref=v3.11.0\n[2d648874-7e47-496d-8d48-b307b98254c1/build]   \u2601  git clone 'https://github.com/actions/cache' # ref=v3\n[2d648874-7e47-496d-8d48-b307b98254c1/build] \u2b50 Run Main actions/checkout@v3\n[2d648874-7e47-496d-8d48-b307b98254c1/build]   \u2705  Success - Main actions/checkout@v3\n[2d648874-7e47-496d-8d48-b307b98254c1/build] \u2b50 Run Main Start dependencies with docker-compose\n[2d648874-7e47-496d-8d48-b307b98254c1/build]   \ud83d\udc33  docker exec cmd=[bash --noprofile --norc -e -o pipefail /var/run/act/workflow/1] user= workdir=\n[2d648874-7e47-496d-8d48-b307b98254c1/build]   | [32] Failed to execute script docker-compose\n[2d648874-7e47-496d-8d48-b307b98254c1/build]   | Traceback (most recent call last):\n[2d648874-7e47-496d-8d48-b307b98254c1/build]   |   File \"urllib3/connectionpool.py\", line 677, in urlopen\n[2d648874-7e47-496d-8d48-b307b98254c1/build]   |   File \"urllib3/connectionpool.py\", line 392, in _make_request\n[2d648874-7e47-496d-8d48-b307b98254c1/build]   |   File \"http/client.py\", line 1277, in request\n[2d648874-7e47-496d-8d48-b307b98254c1/build]   |   File \"http/client.py\", line 1323, in _send_request\n[2d648874-7e47-496d-8d48-b307b98254c1/build]   |   File \"http/client.py\", line 1272, in endheaders\n[2d648874-7e47-496d-8d48-b307b98254c1/build]   |   File \"http/client.py\", line 1032, in _send_output\n[2d648874-7e47-496d-8d48-b307b98254c1/build]   |   File \"http/client.py\", line 972, in send\n[2d648874-7e47-496d-8d48-b307b98254c1/build]   |   File \"docker/transport/unixconn.py\", line 43, in connect\n[2d648874-7e47-496d-8d48-b307b98254c1/build]   | PermissionError: [Errno 13] Permission denied\n[2d648874-7e47-496d-8d48-b307b98254c1/build]   | \n[2d648874-7e47-496d-8d48-b307b98254c1/build]   | During handling of the above exception, another exception occurred:\n[2d648874-7e47-496d-8d48-b307b98254c1/build]   | \n[2d648874-7e47-496d-8d48-b307b98254c1/build]   | Traceback (most recent call last):\n[2d648874-7e47-496d-8d48-b307b98254c1/build]   |   File \"requests/adapters.py\", line 449, in send\n[2d648874-7e47-496d-8d48-b307b98254c1/build]   |   File \"urllib3/connectionpool.py\", line 727, in urlopen\n[2d648874-7e47-496d-8d48-b307b98254c1/build]   |   File \"urllib3/util/retry.py\", line 410, in increment\n[2d648874-7e47-496d-8d48-b307b98254c1/build]   |   File \"urllib3/packages/six.py\", line 734, in reraise\n[2d648874-7e47-496d-8d48-b307b98254c1/build]   |   File \"urllib3/connectionpool.py\", line 677, in urlopen\n[2d648874-7e47-496d-8d48-b307b98254c1/build]   |   File \"urllib3/connectionpool.py\", line 392, in _make_request\n[2d648874-7e47-496d-8d48-b307b98254c1/build]   |   File \"http/client.py\", line 1277, in request\n[2d648874-7e47-496d-8d48-b307b98254c1/build]   |   File \"http/client.py\", line 1323, in _send_request\n[2d648874-7e47-496d-8d48-b307b98254c1/build]   |   File \"http/client.py\", line 1272, in endheaders\n[2d648874-7e47-496d-8d48-b307b98254c1/build]   |   File \"http/client.py\", line 1032, in _send_output\n[2d648874-7e47-496d-8d48-b307b98254c1/build]   |   File \"http/client.py\", line 972, in send\n[2d648874-7e47-496d-8d48-b307b98254c1/build]   |   File \"docker/transport/unixconn.py\", line 43, in connect\n[2d648874-7e47-496d-8d48-b307b98254c1/build]   | urllib3.exceptions.ProtocolError: ('Connection aborted.', PermissionError(13, 'Permission denied'))\n[2d648874-7e47-496d-8d48-b307b98254c1/build]   | \n[2d648874-7e47-496d-8d48-b307b98254c1/build]   | During handling of the above exception, another exception occurred:\n[2d648874-7e47-496d-8d48-b307b98254c1/build]   | \n[2d648874-7e47-496d-8d48-b307b98254c1/build]   | Traceback (most recent call last):\n[2d648874-7e47-496d-8d48-b307b98254c1/build]   |   File \"docker/api/client.py\", line 214, in _retrieve_server_version\n[2d648874-7e47-496d-8d48-b307b98254c1/build]   |   File \"docker/api/daemon.py\", line 181, in version\n[2d648874-7e47-496d-8d48-b307b98254c1/build]   |   File \"docker/utils/decorators.py\", line 46, in inner\n[2d648874-7e47-496d-8d48-b307b98254c1/build]   |   File \"docker/api/client.py\", line 237, in _get\n[2d648874-7e47-496d-8d48-b307b98254c1/build]   |   File \"requests/sessions.py\", line 543, in get\n[2d648874-7e47-496d-8d48-b307b98254c1/build]   |   File \"requests/sessions.py\", line 530, in request\n[2d648874-7e47-496d-8d48-b307b98254c1/build]   |   File \"requests/sessions.py\", line 643, in send\n[2d648874-7e47-496d-8d48-b307b98254c1/build]   |   File \"requests/adapters.py\", line 498, in send\n[2d648874-7e47-496d-8d48-b307b98254c1/build]   | requests.exceptions.ConnectionError: ('Connection aborted.', PermissionError(13, 'Permission denied'))\n[2d648874-7e47-496d-8d48-b307b98254c1/build]   | \n[2d648874-7e47-496d-8d48-b307b98254c1/build]   | During handling of the above exception, another exception occurred:\n[2d648874-7e47-496d-8d48-b307b98254c1/build]   | \n[2d648874-7e47-496d-8d48-b307b98254c1/build]   | Traceback (most recent call last):\n[2d648874-7e47-496d-8d48-b307b98254c1/build]   |   File \"docker-compose\", line 3, in <module>\n[2d648874-7e47-496d-8d48-b307b98254c1/build]   |   File \"compose/cli/main.py\", line 81, in main\n[2d648874-7e47-496d-8d48-b307b98254c1/build]   |   File \"compose/cli/main.py\", line 200, in perform_command\n[2d648874-7e47-496d-8d48-b307b98254c1/build]   |   File \"compose/cli/command.py\", line 70, in project_from_options\n[2d648874-7e47-496d-8d48-b307b98254c1/build]   |   File \"compose/cli/command.py\", line 153, in get_project\n[2d648874-7e47-496d-8d48-b307b98254c1/build]   |   File \"compose/cli/docker_client.py\", line 43, in get_client\n[2d648874-7e47-496d-8d48-b307b98254c1/build]   |   File \"compose/cli/docker_client.py\", line 170, in docker_client\n[2d648874-7e47-496d-8d48-b307b98254c1/build]   |   File \"docker/api/client.py\", line 197, in __init__\n[2d648874-7e47-496d-8d48-b307b98254c1/build]   |   File \"docker/api/client.py\", line 222, in _retrieve_server_version\n[2d648874-7e47-496d-8d48-b307b98254c1/build]   | docker.errors.DockerException: Error while fetching server API version: ('Connection aborted.', PermissionError(13, 'Permission denied'))\n[2d648874-7e47-496d-8d48-b307b98254c1/build]   \u274c  Failure - Main Start dependencies with docker-compose\n[2d648874-7e47-496d-8d48-b307b98254c1/build] exitcode '255': failure\n[2d648874-7e47-496d-8d48-b307b98254c1/build] \u2b50 Run Main Stop dependencies with docker-compose\n[2d648874-7e47-496d-8d48-b307b98254c1/build]   \ud83d\udc33  docker exec cmd=[bash --noprofile --norc -e -o pipefail /var/run/act/workflow/8] user= workdir=\n[2d648874-7e47-496d-8d48-b307b98254c1/build]   | [42] Failed to execute script docker-compose\n[2d648874-7e47-496d-8d48-b307b98254c1/build]   | Traceback (most recent call last):\n[2d648874-7e47-496d-8d48-b307b98254c1/build]   |   File \"urllib3/connectionpool.py\", line 677, in urlopen\n[2d648874-7e47-496d-8d48-b307b98254c1/build]   |   File \"urllib3/connectionpool.py\", line 392, in _make_request\n[2d648874-7e47-496d-8d48-b307b98254c1/build]   |   File \"http/client.py\", line 1277, in request\n[2d648874-7e47-496d-8d48-b307b98254c1/build]   |   File \"http/client.py\", line 1323, in _send_request\n[2d648874-7e47-496d-8d48-b307b98254c1/build]   |   File \"http/client.py\", line 1272, in endheaders\n[2d648874-7e47-496d-8d48-b307b98254c1/build]   |   File \"http/client.py\", line 1032, in _send_output\n[2d648874-7e47-496d-8d48-b307b98254c1/build]   |   File \"http/client.py\", line 972, in send\n[2d648874-7e47-496d-8d48-b307b98254c1/build]   |   File \"docker/transport/unixconn.py\", line 43, in connect\n[2d648874-7e47-496d-8d48-b307b98254c1/build]   | PermissionError: [Errno 13] Permission denied\n[2d648874-7e47-496d-8d48-b307b98254c1/build]   | \n[2d648874-7e47-496d-8d48-b307b98254c1/build]   | During handling of the above exception, another exception occurred:\n[2d648874-7e47-496d-8d48-b307b98254c1/build]   | \n[2d648874-7e47-496d-8d48-b307b98254c1/build]   | Traceback (most recent call last):\n[2d648874-7e47-496d-8d48-b307b98254c1/build]   |   File \"requests/adapters.py\", line 449, in send\n[2d648874-7e47-496d-8d48-b307b98254c1/build]   |   File \"urllib3/connectionpool.py\", line 727, in urlopen\n[2d648874-7e47-496d-8d48-b307b98254c1/build]   |   File \"urllib3/util/retry.py\", line 410, in increment\n[2d648874-7e47-496d-8d48-b307b98254c1/build]   |   File \"urllib3/packages/six.py\", line 734, in reraise\n[2d648874-7e47-496d-8d48-b307b98254c1/build]   |   File \"urllib3/connectionpool.py\", line 677, in urlopen\n[2d648874-7e47-496d-8d48-b307b98254c1/build]   |   File \"urllib3/connectionpool.py\", line 392, in _make_request\n[2d648874-7e47-496d-8d48-b307b98254c1/build]   |   File \"http/client.py\", line 1277, in request\n[2d648874-7e47-496d-8d48-b307b98254c1/build]   |   File \"http/client.py\", line 1323, in _send_request\n[2d648874-7e47-496d-8d48-b307b98254c1/build]   |   File \"http/client.py\", line 1272, in endheaders\n[2d648874-7e47-496d-8d48-b307b98254c1/build]   |   File \"http/client.py\", line 1032, in _send_output\n[2d648874-7e47-496d-8d48-b307b98254c1/build]   |   File \"http/client.py\", line 972, in send\n[2d648874-7e47-496d-8d48-b307b98254c1/build]   |   File \"docker/transport/unixconn.py\", line 43, in connect\n[2d648874-7e47-496d-8d48-b307b98254c1/build]   | urllib3.exceptions.ProtocolError: ('Connection aborted.', PermissionError(13, 'Permission denied'))\n[2d648874-7e47-496d-8d48-b307b98254c1/build]   | \n[2d648874-7e47-496d-8d48-b307b98254c1/build]   | During handling of the above exception, another exception occurred:\n[2d648874-7e47-496d-8d48-b307b98254c1/build]   | \n[2d648874-7e47-496d-8d48-b307b98254c1/build]   | Traceback (most recent call last):\n[2d648874-7e47-496d-8d48-b307b98254c1/build]   |   File \"docker/api/client.py\", line 214, in _retrieve_server_version\n[2d648874-7e47-496d-8d48-b307b98254c1/build]   |   File \"docker/api/daemon.py\", line 181, in version\n[2d648874-7e47-496d-8d48-b307b98254c1/build]   |   File \"docker/utils/decorators.py\", line 46, in inner\n[2d648874-7e47-496d-8d48-b307b98254c1/build]   |   File \"docker/api/client.py\", line 237, in _get\n[2d648874-7e47-496d-8d48-b307b98254c1/build]   |   File \"requests/sessions.py\", line 543, in get\n[2d648874-7e47-496d-8d48-b307b98254c1/build]   |   File \"requests/sessions.py\", line 530, in request\n[2d648874-7e47-496d-8d48-b307b98254c1/build]   |   File \"requests/sessions.py\", line 643, in send\n[2d648874-7e47-496d-8d48-b307b98254c1/build]   |   File \"requests/adapters.py\", line 498, in send\n[2d648874-7e47-496d-8d48-b307b98254c1/build]   | requests.exceptions.ConnectionError: ('Connection aborted.', PermissionError(13, 'Permission denied'))\n[2d648874-7e47-496d-8d48-b307b98254c1/build]   | \n[2d648874-7e47-496d-8d48-b307b98254c1/build]   | During handling of the above exception, another exception occurred:\n[2d648874-7e47-496d-8d48-b307b98254c1/build]   | \n[2d648874-7e47-496d-8d48-b307b98254c1/build]   | Traceback (most recent call last):\n[2d648874-7e47-496d-8d48-b307b98254c1/build]   |   File \"docker-compose\", line 3, in <module>\n[2d648874-7e47-496d-8d48-b307b98254c1/build]   |   File \"compose/cli/main.py\", line 81, in main\n[2d648874-7e47-496d-8d48-b307b98254c1/build]   |   File \"compose/cli/main.py\", line 200, in perform_command\n[2d648874-7e47-496d-8d48-b307b98254c1/build]   |   File \"compose/cli/command.py\", line 70, in project_from_options\n[2d648874-7e47-496d-8d48-b307b98254c1/build]   |   File \"compose/cli/command.py\", line 153, in get_project\n[2d648874-7e47-496d-8d48-b307b98254c1/build]   |   File \"compose/cli/docker_client.py\", line 43, in get_client\n[2d648874-7e47-496d-8d48-b307b98254c1/build]   |   File \"compose/cli/docker_client.py\", line 170, in docker_client\n[2d648874-7e47-496d-8d48-b307b98254c1/build]   |   File \"docker/api/client.py\", line 197, in __init__\n[2d648874-7e47-496d-8d48-b307b98254c1/build]   |   File \"docker/api/client.py\", line 222, in _retrieve_server_version\n[2d648874-7e47-496d-8d48-b307b98254c1/build]   | docker.errors.DockerException: Error while fetching server API version: ('Connection aborted.', PermissionError(13, 'Permission denied'))\n[2d648874-7e47-496d-8d48-b307b98254c1/build]   \u274c  Failure - Main Stop dependencies with docker-compose\n[2d648874-7e47-496d-8d48-b307b98254c1/build] exitcode '255': failure\n[2d648874-7e47-496d-8d48-b307b98254c1/build] \ud83c\udfc1  Job failed\n",
        "stderr": "Error: Job 'build' failed\n",
        "workflow": "/tmp/3d783ea4-1661-11ee-8a50-bb14de238602/andreschaffer-microservices-testing-examples/.github/workflows/build-crawler.yml",
        "build_tool": "maven",
        "elapsed_time": 92.48062419891357
    }
}