{
    "repository": "ungarj/mapchete",
    "stars": 177,
    "language": "python",
    "size": 10542,
    "clone_url": "https://github.com/ungarj/mapchete.git",
    "timestamp": "2023-06-28T10:59:57.825074Z",
    "clone_success": true,
    "number_of_actions": 2,
    "number_of_test_actions": 1,
    "actions_successful": false,
    "actions_build_tools": [
        "pytest",
        "unknown"
    ],
    "actions_test_build_tools": [
        "pytest"
    ],
    "actions_run": {
        "failed": true,
        "tests": [],
        "stdout": "[65026448-8444-4290-b20b-9a2c61c2189a/test] \ud83d\ude80  Start image=crawlergpt:latest\n[65026448-8444-4290-b20b-9a2c61c2189a/test]   \ud83d\udc33  docker pull image=crawlergpt:latest platform= username= forcePull=false\n[65026448-8444-4290-b20b-9a2c61c2189a/test]   \ud83d\udc33  docker create image=crawlergpt:latest platform= entrypoint=[\"tail\" \"-f\" \"/dev/null\"] cmd=[]\n[65026448-8444-4290-b20b-9a2c61c2189a/test]   \ud83d\udc33  docker run image=crawlergpt:latest platform= entrypoint=[\"tail\" \"-f\" \"/dev/null\"] cmd=[]\n[65026448-8444-4290-b20b-9a2c61c2189a/test]   \ud83d\udc33  docker exec cmd=[chown -R 1012:1013 /tmp/ad9c0f7e-1596-11ee-8a50-bb14de238602/ungarj-mapchete] user=0 workdir=\n[65026448-8444-4290-b20b-9a2c61c2189a/test]   \u2601  git clone 'https://github.com/actions/setup-python' # ref=v2\n[65026448-8444-4290-b20b-9a2c61c2189a/test] \ud83e\uddea  Matrix: map[os:ubuntu-latest python-version:3.8]\n[65026448-8444-4290-b20b-9a2c61c2189a/test] \u2b50 Run Main actions/checkout@v2\n[65026448-8444-4290-b20b-9a2c61c2189a/test]   \u2705  Success - Main actions/checkout@v2\n[65026448-8444-4290-b20b-9a2c61c2189a/test] \u2b50 Run Main Set up Python 3.8\n[65026448-8444-4290-b20b-9a2c61c2189a/test]   \ud83d\udc33  docker cp src=/tmp/act-cache/0f106557-b9ee-495d-9209-3c4bf829a29b/act/actions-setup-python@v2/ dst=/var/run/act/actions/actions-setup-python@v2/\n[65026448-8444-4290-b20b-9a2c61c2189a/test]   \ud83d\udc33  docker exec cmd=[chown -R 1012:1013 /var/run/act/actions/actions-setup-python@v2/] user=0 workdir=\n[65026448-8444-4290-b20b-9a2c61c2189a/test]   \ud83d\udc33  docker exec cmd=[node /var/run/act/actions/actions-setup-python@v2/dist/setup/index.js] user= workdir=\n[65026448-8444-4290-b20b-9a2c61c2189a/test]   \ud83d\udcac  ::debug::Semantic version spec of 3.8 is 3.8\n[65026448-8444-4290-b20b-9a2c61c2189a/test]   \ud83d\udcac  ::debug::isExplicit: \n[65026448-8444-4290-b20b-9a2c61c2189a/test]   \ud83d\udcac  ::debug::explicit? false\n[65026448-8444-4290-b20b-9a2c61c2189a/test]   \ud83d\udcac  ::debug::isExplicit: 2.7.18\n[65026448-8444-4290-b20b-9a2c61c2189a/test]   \ud83d\udcac  ::debug::explicit? true\n[65026448-8444-4290-b20b-9a2c61c2189a/test]   \ud83d\udcac  ::debug::isExplicit: 3.5.10\n[65026448-8444-4290-b20b-9a2c61c2189a/test]   \ud83d\udcac  ::debug::explicit? true\n[65026448-8444-4290-b20b-9a2c61c2189a/test]   \ud83d\udcac  ::debug::isExplicit: 3.6.14\n[65026448-8444-4290-b20b-9a2c61c2189a/test]   \ud83d\udcac  ::debug::explicit? true\n[65026448-8444-4290-b20b-9a2c61c2189a/test]   \ud83d\udcac  ::debug::isExplicit: 3.7.11\n[65026448-8444-4290-b20b-9a2c61c2189a/test]   \ud83d\udcac  ::debug::explicit? true\n[65026448-8444-4290-b20b-9a2c61c2189a/test]   \ud83d\udcac  ::debug::isExplicit: 3.8.11\n[65026448-8444-4290-b20b-9a2c61c2189a/test]   \ud83d\udcac  ::debug::explicit? true\n[65026448-8444-4290-b20b-9a2c61c2189a/test]   \ud83d\udcac  ::debug::isExplicit: 3.9.6\n[65026448-8444-4290-b20b-9a2c61c2189a/test]   \ud83d\udcac  ::debug::explicit? true\n[65026448-8444-4290-b20b-9a2c61c2189a/test]   \ud83d\udcac  ::debug::evaluating 6 versions\n[65026448-8444-4290-b20b-9a2c61c2189a/test]   \ud83d\udcac  ::debug::matched: 3.8.11\n[65026448-8444-4290-b20b-9a2c61c2189a/test]   \ud83d\udcac  ::debug::checking cache: /opt/hostedtoolcache/Python/3.8.11/x64\n[65026448-8444-4290-b20b-9a2c61c2189a/test]   \ud83d\udcac  ::debug::Found tool in cache Python 3.8.11 x64\n[65026448-8444-4290-b20b-9a2c61c2189a/test]   | Successfully setup CPython (3.8.11)\n[65026448-8444-4290-b20b-9a2c61c2189a/test]   \u2753 add-matcher /run/act/actions/actions-setup-python@v2/.github/python.json\n[65026448-8444-4290-b20b-9a2c61c2189a/test]   \u2705  Success - Main Set up Python 3.8\n[65026448-8444-4290-b20b-9a2c61c2189a/test]   \u2699  ::set-env:: pythonLocation=/opt/hostedtoolcache/Python/3.8.11/x64\n[65026448-8444-4290-b20b-9a2c61c2189a/test]   \u2699  ::set-env:: LD_LIBRARY_PATH=/opt/hostedtoolcache/Python/3.8.11/x64/lib\n[65026448-8444-4290-b20b-9a2c61c2189a/test]   \u2699  ::set-output:: python-version=3.8.11\n[65026448-8444-4290-b20b-9a2c61c2189a/test]   \u2699  ::add-path:: /opt/hostedtoolcache/Python/3.8.11/x64\n[65026448-8444-4290-b20b-9a2c61c2189a/test]   \u2699  ::add-path:: /opt/hostedtoolcache/Python/3.8.11/x64/bin\n[65026448-8444-4290-b20b-9a2c61c2189a/test] \u2b50 Run Main Install dependencies\n[65026448-8444-4290-b20b-9a2c61c2189a/test]   \ud83d\udc33  docker exec cmd=[bash --noprofile --norc -e -o pipefail /var/run/act/workflow/2] user= workdir=\n[65026448-8444-4290-b20b-9a2c61c2189a/test]   | Ign:1 https://dl.hhvm.com/ubuntu focal InRelease\n[65026448-8444-4290-b20b-9a2c61c2189a/test]   | Hit:2 http://ppa.launchpad.net/ubuntu-toolchain-r/test/ubuntu focal InRelease\n[65026448-8444-4290-b20b-9a2c61c2189a/test]   | Err:3 https://dl.hhvm.com/ubuntu focal Release\n[65026448-8444-4290-b20b-9a2c61c2189a/test]   |   Certificate verification failed: The certificate is NOT trusted. The certificate issuer is unknown.  Could not handshake: Error in the certificate verification. [IP: 108.157.214.95 443]\n[65026448-8444-4290-b20b-9a2c61c2189a/test]   | Get:4 http://ppa.launchpad.net/ubuntugis/ubuntugis-unstable/ubuntu focal InRelease [23.8 kB]\n[65026448-8444-4290-b20b-9a2c61c2189a/test]   | Get:5 http://dl.google.com/linux/chrome/deb stable InRelease [1825 B]\n[65026448-8444-4290-b20b-9a2c61c2189a/test]   | Get:6 https://packages.microsoft.com/ubuntu/20.04/prod focal InRelease [3611 B]\n[65026448-8444-4290-b20b-9a2c61c2189a/test]   | Hit:7 http://archive.ubuntu.com/ubuntu focal InRelease\n[65026448-8444-4290-b20b-9a2c61c2189a/test]   | Get:8 http://security.ubuntu.com/ubuntu focal-security InRelease [114 kB]\n[65026448-8444-4290-b20b-9a2c61c2189a/test]   | Get:9 http://archive.ubuntu.com/ubuntu focal-updates InRelease [114 kB]\n[65026448-8444-4290-b20b-9a2c61c2189a/test]   | Hit:10 https://adoptopenjdk.jfrog.io/adoptopenjdk/deb focal InRelease\n[65026448-8444-4290-b20b-9a2c61c2189a/test]   | Err:5 http://dl.google.com/linux/chrome/deb stable InRelease\n[65026448-8444-4290-b20b-9a2c61c2189a/test]   |   The following signatures couldn't be verified because the public key is not available: NO_PUBKEY 4EB27DB2A3B88B8B\n[65026448-8444-4290-b20b-9a2c61c2189a/test]   | Get:11 http://archive.ubuntu.com/ubuntu focal-backports InRelease [108 kB]\n[65026448-8444-4290-b20b-9a2c61c2189a/test]   | Get:12 https://packages.microsoft.com/ubuntu/20.04/prod focal/main amd64 Packages [210 kB]\n[65026448-8444-4290-b20b-9a2c61c2189a/test]   | Get:13 https://packages.microsoft.com/ubuntu/20.04/prod focal/main all Packages [2521 B]\n[65026448-8444-4290-b20b-9a2c61c2189a/test]   | Get:14 http://ppa.launchpad.net/ubuntugis/ubuntugis-unstable/ubuntu focal/main amd64 Packages [66.5 kB]\n[65026448-8444-4290-b20b-9a2c61c2189a/test]   | Get:15 http://security.ubuntu.com/ubuntu focal-security/main amd64 Packages [2820 kB]\n[65026448-8444-4290-b20b-9a2c61c2189a/test]   | Get:16 http://security.ubuntu.com/ubuntu focal-security/restricted amd64 Packages [2416 kB]\n[65026448-8444-4290-b20b-9a2c61c2189a/test]   | Get:17 http://archive.ubuntu.com/ubuntu focal-updates/universe amd64 Packages [1362 kB]\n[65026448-8444-4290-b20b-9a2c61c2189a/test]   | Get:18 http://security.ubuntu.com/ubuntu focal-security/universe amd64 Packages [1064 kB]\n[65026448-8444-4290-b20b-9a2c61c2189a/test]   | Get:19 http://security.ubuntu.com/ubuntu focal-security/restricted i386 Packages [36.9 kB]\n[65026448-8444-4290-b20b-9a2c61c2189a/test]   | Get:20 http://security.ubuntu.com/ubuntu focal-security/universe i386 Packages [744 kB]\n[65026448-8444-4290-b20b-9a2c61c2189a/test]   | Get:21 http://security.ubuntu.com/ubuntu focal-security/multiverse amd64 Packages [28.5 kB]\n[65026448-8444-4290-b20b-9a2c61c2189a/test]   | Get:22 http://security.ubuntu.com/ubuntu focal-security/multiverse i386 Packages [8141 B]\n[65026448-8444-4290-b20b-9a2c61c2189a/test]   | Get:23 http://security.ubuntu.com/ubuntu focal-security/main i386 Packages [758 kB]\n[65026448-8444-4290-b20b-9a2c61c2189a/test]   | Get:24 http://archive.ubuntu.com/ubuntu focal-updates/multiverse amd64 Packages [31.2 kB]\n[65026448-8444-4290-b20b-9a2c61c2189a/test]   | Get:25 http://archive.ubuntu.com/ubuntu focal-updates/main amd64 Packages [3314 kB]\n[65026448-8444-4290-b20b-9a2c61c2189a/test]   | Get:26 http://archive.ubuntu.com/ubuntu focal-updates/restricted amd64 Packages [2591 kB]\n[65026448-8444-4290-b20b-9a2c61c2189a/test]   | Get:27 http://archive.ubuntu.com/ubuntu focal-backports/universe amd64 Packages [28.6 kB]\n[65026448-8444-4290-b20b-9a2c61c2189a/test]   | Get:28 http://archive.ubuntu.com/ubuntu focal-backports/main amd64 Packages [55.2 kB]\n[65026448-8444-4290-b20b-9a2c61c2189a/test]   | Get:29 https://cloud.r-project.org/bin/linux/ubuntu focal-cran40/ InRelease [3622 B]\n[65026448-8444-4290-b20b-9a2c61c2189a/test]   | Get:30 https://cloud.r-project.org/bin/linux/ubuntu focal-cran40/ Packages [79.8 kB]\n[65026448-8444-4290-b20b-9a2c61c2189a/test]   | Reading package lists...\n[65026448-8444-4290-b20b-9a2c61c2189a/test]   | E: The repository 'https://dl.hhvm.com/ubuntu focal Release' no longer has a Release file.\n[65026448-8444-4290-b20b-9a2c61c2189a/test]   | W: An error occurred during the signature verification. The repository is not updated and the previous index files will be used. GPG error: http://dl.google.com/linux/chrome/deb stable InRelease: The following signatures couldn't be verified because the public key is not available: NO_PUBKEY 4EB27DB2A3B88B8B\n[65026448-8444-4290-b20b-9a2c61c2189a/test]   \u274c  Failure - Main Install dependencies\n[65026448-8444-4290-b20b-9a2c61c2189a/test] exitcode '100': failure\n[65026448-8444-4290-b20b-9a2c61c2189a/test] \u2b50 Run Main Stop containers\n[65026448-8444-4290-b20b-9a2c61c2189a/test]   \ud83d\udc33  docker exec cmd=[bash --noprofile --norc -e -o pipefail /var/run/act/workflow/7] user= workdir=\n[65026448-8444-4290-b20b-9a2c61c2189a/test]   | [1064] Failed to execute script docker-compose\n[65026448-8444-4290-b20b-9a2c61c2189a/test]   | Traceback (most recent call last):\n[65026448-8444-4290-b20b-9a2c61c2189a/test]   |   File \"urllib3/connectionpool.py\", line 677, in urlopen\n[65026448-8444-4290-b20b-9a2c61c2189a/test]   |   File \"urllib3/connectionpool.py\", line 392, in _make_request\n[65026448-8444-4290-b20b-9a2c61c2189a/test]   |   File \"http/client.py\", line 1277, in request\n[65026448-8444-4290-b20b-9a2c61c2189a/test]   |   File \"http/client.py\", line 1323, in _send_request\n[65026448-8444-4290-b20b-9a2c61c2189a/test]   |   File \"http/client.py\", line 1272, in endheaders\n[65026448-8444-4290-b20b-9a2c61c2189a/test]   |   File \"http/client.py\", line 1032, in _send_output\n[65026448-8444-4290-b20b-9a2c61c2189a/test]   |   File \"http/client.py\", line 972, in send\n[65026448-8444-4290-b20b-9a2c61c2189a/test]   |   File \"docker/transport/unixconn.py\", line 43, in connect\n[65026448-8444-4290-b20b-9a2c61c2189a/test]   | PermissionError: [Errno 13] Permission denied\n[65026448-8444-4290-b20b-9a2c61c2189a/test]   | \n[65026448-8444-4290-b20b-9a2c61c2189a/test]   | During handling of the above exception, another exception occurred:\n[65026448-8444-4290-b20b-9a2c61c2189a/test]   | \n[65026448-8444-4290-b20b-9a2c61c2189a/test]   | Traceback (most recent call last):\n[65026448-8444-4290-b20b-9a2c61c2189a/test]   |   File \"requests/adapters.py\", line 449, in send\n[65026448-8444-4290-b20b-9a2c61c2189a/test]   |   File \"urllib3/connectionpool.py\", line 727, in urlopen\n[65026448-8444-4290-b20b-9a2c61c2189a/test]   |   File \"urllib3/util/retry.py\", line 410, in increment\n[65026448-8444-4290-b20b-9a2c61c2189a/test]   |   File \"urllib3/packages/six.py\", line 734, in reraise\n[65026448-8444-4290-b20b-9a2c61c2189a/test]   |   File \"urllib3/connectionpool.py\", line 677, in urlopen\n[65026448-8444-4290-b20b-9a2c61c2189a/test]   |   File \"urllib3/connectionpool.py\", line 392, in _make_request\n[65026448-8444-4290-b20b-9a2c61c2189a/test]   |   File \"http/client.py\", line 1277, in request\n[65026448-8444-4290-b20b-9a2c61c2189a/test]   |   File \"http/client.py\", line 1323, in _send_request\n[65026448-8444-4290-b20b-9a2c61c2189a/test]   |   File \"http/client.py\", line 1272, in endheaders\n[65026448-8444-4290-b20b-9a2c61c2189a/test]   |   File \"http/client.py\", line 1032, in _send_output\n[65026448-8444-4290-b20b-9a2c61c2189a/test]   |   File \"http/client.py\", line 972, in send\n[65026448-8444-4290-b20b-9a2c61c2189a/test]   |   File \"docker/transport/unixconn.py\", line 43, in connect\n[65026448-8444-4290-b20b-9a2c61c2189a/test]   | urllib3.exceptions.ProtocolError: ('Connection aborted.', PermissionError(13, 'Permission denied'))\n[65026448-8444-4290-b20b-9a2c61c2189a/test]   | \n[65026448-8444-4290-b20b-9a2c61c2189a/test]   | During handling of the above exception, another exception occurred:\n[65026448-8444-4290-b20b-9a2c61c2189a/test]   | \n[65026448-8444-4290-b20b-9a2c61c2189a/test]   | Traceback (most recent call last):\n[65026448-8444-4290-b20b-9a2c61c2189a/test]   |   File \"docker/api/client.py\", line 214, in _retrieve_server_version\n[65026448-8444-4290-b20b-9a2c61c2189a/test]   |   File \"docker/api/daemon.py\", line 181, in version\n[65026448-8444-4290-b20b-9a2c61c2189a/test]   |   File \"docker/utils/decorators.py\", line 46, in inner\n[65026448-8444-4290-b20b-9a2c61c2189a/test]   |   File \"docker/api/client.py\", line 237, in _get\n[65026448-8444-4290-b20b-9a2c61c2189a/test]   |   File \"requests/sessions.py\", line 543, in get\n[65026448-8444-4290-b20b-9a2c61c2189a/test]   |   File \"requests/sessions.py\", line 530, in request\n[65026448-8444-4290-b20b-9a2c61c2189a/test]   |   File \"requests/sessions.py\", line 643, in send\n[65026448-8444-4290-b20b-9a2c61c2189a/test]   |   File \"requests/adapters.py\", line 498, in send\n[65026448-8444-4290-b20b-9a2c61c2189a/test]   | requests.exceptions.ConnectionError: ('Connection aborted.', PermissionError(13, 'Permission denied'))\n[65026448-8444-4290-b20b-9a2c61c2189a/test]   | \n[65026448-8444-4290-b20b-9a2c61c2189a/test]   | During handling of the above exception, another exception occurred:\n[65026448-8444-4290-b20b-9a2c61c2189a/test]   | \n[65026448-8444-4290-b20b-9a2c61c2189a/test]   | Traceback (most recent call last):\n[65026448-8444-4290-b20b-9a2c61c2189a/test]   |   File \"docker-compose\", line 3, in <module>\n[65026448-8444-4290-b20b-9a2c61c2189a/test]   |   File \"compose/cli/main.py\", line 81, in main\n[65026448-8444-4290-b20b-9a2c61c2189a/test]   |   File \"compose/cli/main.py\", line 200, in perform_command\n[65026448-8444-4290-b20b-9a2c61c2189a/test]   |   File \"compose/cli/command.py\", line 70, in project_from_options\n[65026448-8444-4290-b20b-9a2c61c2189a/test]   |   File \"compose/cli/command.py\", line 153, in get_project\n[65026448-8444-4290-b20b-9a2c61c2189a/test]   |   File \"compose/cli/docker_client.py\", line 43, in get_client\n[65026448-8444-4290-b20b-9a2c61c2189a/test]   |   File \"compose/cli/docker_client.py\", line 170, in docker_client\n[65026448-8444-4290-b20b-9a2c61c2189a/test]   |   File \"docker/api/client.py\", line 197, in __init__\n[65026448-8444-4290-b20b-9a2c61c2189a/test]   |   File \"docker/api/client.py\", line 222, in _retrieve_server_version\n[65026448-8444-4290-b20b-9a2c61c2189a/test]   | docker.errors.DockerException: Error while fetching server API version: ('Connection aborted.', PermissionError(13, 'Permission denied'))\n[65026448-8444-4290-b20b-9a2c61c2189a/test]   \u274c  Failure - Main Stop containers\n[65026448-8444-4290-b20b-9a2c61c2189a/test] exitcode '255': failure\n[65026448-8444-4290-b20b-9a2c61c2189a/test] \ud83c\udfc1  Job failed\n",
        "stderr": "Error: Job 'test' failed\n",
        "workflow": "/tmp/ad9c0f7e-1596-11ee-8a50-bb14de238602/ungarj-mapchete/.github/workflows/python-package-crawler.yml",
        "build_tool": "pytest",
        "elapsed_time": 131.96824479103088
    }
}